<?xml version="1.0"?>
<robot name="scara_robot">
  <material name="blue">
    <color rgba="0.0 0.0 1.0 1.0" />
  </material>
  <material name="black">
    <color rgba="0.0 0.0 0.0 1.0" />
  </material>
  <material name="white">
    <color rgba="1.0 1.0 1.0 1.0" />
  </material>

  <link name="world" />
  <link name="base_link">
    <visual>
      <origin xyz="0.0 0.0 0.4" rpy="0.0 0.0 0.0" />
      <geometry>
        <cylinder length="0.8" radius="0.1" />
      </geometry>
      <material name="black" />
    </visual>
  </link>
  <joint name="base_joint" type="fixed">
    <parent link="world" />
    <child link="base_link" />
  </joint>

  <link name="arm1">
    <visual>
      <origin xyz="0.0 -0.5 0.0" rpy="0.0 0.0 0.0" />
      <geometry>
        <box size="0.1 1.0 0.1" />
      </geometry>
      <material name="white" />
    </visual>
  </link>
  <joint name="arm1_joint" type="revolute">
    <origin xyz="0.0 0.0 0.8" rpy="0.0 0.0 0.0" />
    <parent link="base_link" />
    <child link="arm1" />
    <axis xyz="0.0 0.0 1.0" />
    <limit lower="-1.0" upper="1.0" effort="1000.0" velocity="1000.0" />
  </joint>

  <link name="arm2">
    <visual>
      <origin xyz="0.0 -0.25 0.0" rpy="0.0 0.0 0.0" />
      <geometry>
        <box size="0.1 0.5 0.1" />
      </geometry>
      <material name="blue" />
    </visual>
  </link>
  <joint name="arm2_joint" type="revolute">
    <origin xyz="0.0 -1.0 0.0" rpy="0.0 0.0 0.0" />
    <parent link="arm1" />
    <child link="arm2" />
    <axis xyz="0.0 0.0 1.0" />
    <limit lower="-1.0" upper="1.0" effort="1000.0" velocity="1000.0" />
  </joint>
</robot>